Workbook

Sheet DATA
A1: time | B1: tavg | C1: tmin | D1: tmax | E1: prcp | F1: is outlier B | G1: is outlier C | H1: is outlier D | I1: is outlier E | J1: Year | K1: Month
A2: 42757 | B2: 23.3 | C2: 16.8 | D2: 29.1 | E2: 0 | F2: =IF(OR(B2<outliers!$B$7,B2>outliers!$B$6),"Outlier","Normal") -> Normal | G2: =IF(OR(C2<outliers!$B$14,C2>outliers!$B$13),"Outlier","Normal") -> Outlier | H2: =IF(OR(D2<outliers!$B$21,D2>outliers!$B$20),"Outlier","Normal") -> Normal | I2: =IF(OR(E2<outliers!$C$28,E2>outliers!$B$27),"Outlier","Normal") -> Normal | J2: =YEAR(A2) -> 2017 | K2: =TEXT(A1,"mmmm") -> time
A3: 42761 | B3: 21.9 | C3: 18.3 | D3: 29.2 | E3: 0 | F3: =IF(OR(B3<outliers!$B$7,B3>outliers!$B$6),"Outlier","Normal") -> Normal | G3: =IF(OR(C3<outliers!$B$14,C3>outliers!$B$13),"Outlier","Normal") -> Normal | H3: =IF(OR(D3<outliers!$B$21,D3>outliers!$B$20),"Outlier","Normal") -> Normal | I3: =IF(OR(E3<outliers!$C$28,E3>outliers!$B$27),"Outlier","Normal") -> Normal | J3: =YEAR(A3) -> 2017 | K3: =TEXT(A2,"mmmm") -> January
A4: 42762 | B4: 22.1 | C4: 19.7 | D4: 26 | E4: 0.3 | F4: =IF(OR(B4<outliers!$B$7,B4>outliers!$B$6),"Outlier","Normal") -> Normal | G4: =IF(OR(C4<outliers!$B$14,C4>outliers!$B$13),"Outlier","Normal") -> Normal | H4: =IF(OR(D4<outliers!$B$21,D4>outliers!$B$20),"Outlier","Normal") -> Normal | I4: =IF(OR(E4<outliers!$C$28,E4>outliers!$B$27),"Outlier","Normal") -> Normal | J4: =YEAR(A4) -> 2017 | K4: =TEXT(A3,"mmmm") -> January
A5: 42763 | B5: 22.7 | C5: 20 | D5: 26.7 | E5: 0 | F5: =IF(OR(B5<outliers!$B$7,B5>outliers!$B$6),"Outlier","Normal") -> Normal | G5: =IF(OR(C5<outliers!$B$14,C5>outliers!$B$13),"Outlier","Normal") -> Normal | H5: =IF(OR(D5<outliers!$B$21,D5>outliers!$B$20),"Outlier","Normal") -> Normal | I5: =IF(OR(E5<outliers!$C$28,E5>outliers!$B$27),"Outlier","Normal") -> Normal | J5: =YEAR(A5) -> 2017 | K5: =TEXT(A4,"mmmm") -> January
A6: 42764 | B6: 23.7 | C6: 19.2 | D6: 29 | E6: 0 | F6: =IF(OR(B6<outliers!$B$7,B6>outliers!$B$6),"Outlier","Normal") -> Normal | G6: =IF(OR(C6<outliers!$B$14,C6>outliers!$B$13),"Outlier","Normal") -> Normal | H6: =IF(OR(D6<outliers!$B$21,D6>outliers!$B$20),"Outlier","Normal") -> Normal | I6: =IF(OR(E6<outliers!$C$28,E6>outliers!$B$27),"Outlier","Normal") -> Normal | J6: =YEAR(A6) -> 2017 | K6: =TEXT(A5,"mmmm") -> January
A7: 42801 | B7: 26.2 | C7: 21.5 | D7: 33.1 | E7: 8.4 | F7: =IF(OR(B7<outliers!$B$7,B7>outliers!$B$6),"Outlier","Normal") -> Normal | G7: =IF(OR(C7<outliers!$B$14,C7>outliers!$B$13),"Outlier","Normal") -> Normal | H7: =IF(OR(D7<outliers!$B$21,D7>outliers!$B$20),"Outlier","Normal") -> Normal | I7: =IF(OR(E7<outliers!$C$28,E7>outliers!$B$27),"Outlier","Normal") -> Normal | J7: =YEAR(A7) -> 2017 | K7: =TEXT(A6,"mmmm") -> January
A8: 42802 | B8: 25.6 | C8: 21.1 | D8: 33.8 | E8: 36.8 | F8: =IF(OR(B8<outliers!$B$7,B8>outliers!$B$6),"Outlier","Normal") -> Normal | G8: =IF(OR(C8<outliers!$B$14,C8>outliers!$B$13),"Outlier","Normal") -> Normal | H8: =IF(OR(D8<outliers!$B$21,D8>outliers!$B$20),"Outlier","Normal") -> Normal | I8: =IF(OR(E8<outliers!$C$28,E8>outliers!$B$27),"Outlier","Normal") -> Outlier | J8: =YEAR(A8) -> 2017 | K8: =TEXT(A7,"mmmm") -> March
A9: 42803 | B9: 26.7 | C9: 21.2 | D9: 32.1 | E9: 0 | F9: =IF(OR(B9<outliers!$B$7,B9>outliers!$B$6),"Outlier","Normal") -> Normal | G9: =IF(OR(C9<outliers!$B$14,C9>outliers!$B$13),"Outlier","Normal") -> Normal | H9: =IF(OR(D9<outliers!$B$21,D9>outliers!$B$20),"Outlier","Normal") -> Normal | I9: =IF(OR(E9<outliers!$C$28,E9>outliers!$B$27),"Outlier","Normal") -> Normal | J9: =YEAR(A9) -> 2017 | K9: =TEXT(A8,"mmmm") -> March
A10: 42805 | B10: 27.2 | C10: 21 | D10: 33.5 | E10: 0 | F10: =IF(OR(B10<outliers!$B$7,B10>outliers!$B$6),"Outlier","Normal") -> Normal | G10: =IF(OR(C10<outliers!$B$14,C10>outliers!$B$13),"Outlier","Normal") -> Normal | H10: =IF(OR(D10<outliers!$B$21,D10>outliers!$B$20),"Outlier","Normal") -> Normal | I10: =IF(OR(E10<outliers!$C$28,E10>outliers!$B$27),"Outlier","Normal") -> Normal | J10: =YEAR(A10) -> 2017 | K10: =TEXT(A9,"mmmm") -> March
A11: 42808 | B11: 25.1 | C11: 22 | D11: 34 | E11: 0 | F11: =IF(OR(B11<outliers!$B$7,B11>outliers!$B$6),"Outlier","Normal") -> Normal | G11: =IF(OR(C11<outliers!$B$14,C11>outliers!$B$13),"Outlier","Normal") -> Normal | H11: =IF(OR(D11<outliers!$B$21,D11>outliers!$B$20),"Outlier","Normal") -> Normal | I11: =IF(OR(E11<outliers!$C$28,E11>outliers!$B$27),"Outlier","Normal") -> Normal | J11: =YEAR(A11) -> 2017 | K11: =TEXT(A10,"mmmm") -> March
A12: 42809 | B12: 25.3 | C12: 20.8 | D12: 30.4 | E12: 0 | F12: =IF(OR(B12<outliers!$B$7,B12>outliers!$B$6),"Outlier","Normal") -> Normal | G12: =IF(OR(C12<outliers!$B$14,C12>outliers!$B$13),"Outlier","Normal") -> Normal | H12: =IF(OR(D12<outliers!$B$21,D12>outliers!$B$20),"Outlier","Normal") -> Normal | I12: =IF(OR(E12<outliers!$C$28,E12>outliers!$B$27),"Outlier","Normal") -> Normal | J12: =YEAR(A12) -> 2017 | K12: =TEXT(A11,"mmmm") -> March
A13: 42830 | B13: 27.3 | C13: 21.2 | D13: 36.1 | E13: 0 | F13: =IF(OR(B13<outliers!$B$7,B13>outliers!$B$6),"Outlier","Normal") -> Normal | G13: =IF(OR(C13<outliers!$B$14,C13>outliers!$B$13),"Outlier","Normal") -> Normal | H13: =IF(OR(D13<outliers!$B$21,D13>outliers!$B$20),"Outlier","Normal") -> Normal | I13: =IF(OR(E13<outliers!$C$28,E13>outliers!$B$27),"Outlier","Normal") -> Normal | J13: =YEAR(A13) -> 2017 | K13: =TEXT(A12,"mmmm") -> March
... A59: 42904 | B59: 23.8 | C59: 20.2 | D59: 29.3 | E59: 0 | F59: =IF(OR(B59<outliers!$B$7,B59>outliers!$B$6),"Outlier","Normal") -> Normal | G59: =IF(OR(C59<outliers!$B$14,C59>outliers!$B$13),"Outlier","Normal") -> Normal | H59: =IF(OR(D59<outliers!$B$21,D59>outliers!$B$20),"Outlier","Normal") -> Normal | I59: =IF(OR(E59<outliers!$C$28,E59>outliers!$B$27),"Outlier","Normal") -> Normal | J59: =YEAR(A59) -> 2017 | K59: =TEXT(A58,"mmmm") -> June
A60: 42905 | B60: 23.4 | C60: 20 | D60: 29 | E60: 3.6 | F60: =IF(OR(B60<outliers!$B$7,B60>outliers!$B$6),"Outlier","Normal") -> Normal | G60: =IF(OR(C60<outliers!$B$14,C60>outliers!$B$13),"Outlier","Normal") -> Normal | H60: =IF(OR(D60<outliers!$B$21,D60>outliers!$B$20),"Outlier","Normal") -> Normal | I60: =IF(OR(E60<outliers!$C$28,E60>outliers!$B$27),"Outlier","Normal") -> Normal | J60: =YEAR(A60) -> 2017 | K60: =TEXT(A59,"mmmm") -> June | Q60: Row Labels | R60: Sum of tavg | S60: Sum of prcp
A61: 42906 | B61: 24.1 | C61: 21 | D61: 28 | E61: 0 | F61: =IF(OR(B61<outliers!$B$7,B61>outliers!$B$6),"Outlier","Normal") -> Normal | G61: =IF(OR(C61<outliers!$B$14,C61>outliers!$B$13),"Outlier","Normal") -> Normal | H61: =IF(OR(D61<outliers!$B$21,D61>outliers!$B$20),"Outlier","Normal") -> Normal | I61: =IF(OR(E61<outliers!$C$28,E61>outliers!$B$27),"Outlier","Normal") -> Normal | J61: =YEAR(A61) -> 2017 | K61: =TEXT(A60,"mmmm") -> June | Q61: January | R61: 1587.9 | S61: 30.4
A62: 42907 | B62: 24.6 | C62: 20.8 | D62: 29.8 | E62: 0.3 | F62: =IF(OR(B62<outliers!$B$7,B62>outliers!$B$6),"Outlier","Normal") -> Normal | G62: =IF(OR(C62<outliers!$B$14,C62>outliers!$B$13),"Outlier","Normal") -> Normal | H62: =IF(OR(D62<outliers!$B$21,D62>outliers!$B$20),"Outlier","Normal") -> Normal | I62: =IF(OR(E62<outliers!$C$28,E62>outliers!$B$27),"Outlier","Normal") -> Normal | J62: =YEAR(A62) -> 2017 | K62: =TEXT(A61,"mmmm") -> June | Q62: February | R62: 1378.5 | S62: 12.6
A63: 42908 | B63: 24.4 | C63: 20.5 | D63: 29.5 | E63: 0 | F63: =IF(OR(B63<outliers!$B$7,B63>outliers!$B$6),"Outlier","Normal") -> Normal | G63: =IF(OR(C63<outliers!$B$14,C63>outliers!$B$13),"Outlier","Normal") -> Normal | H63: =IF(OR(D63<outliers!$B$21,D63>outliers!$B$20),"Outlier","Normal") -> Normal | I63: =IF(OR(E63<outliers!$C$28,E63>outliers!$B$27),"Outlier","Normal") -> Normal | J63: =YEAR(A63) -> 2017 | K63: =TEXT(A62,"mmmm") -> June | Q63: March | R63: 2207.5 | S63: 105.7
A64: 42909 | B64: 24.9 | C64: 19.4 | D64: 30.6 | E64: 0.8 | F64: =IF(OR(B64<outliers!$B$7,B64>outliers!$B$6),"Outlier","Normal") -> Normal | G64: =IF(OR(C64<outliers!$B$14,C64>outliers!$B$13),"Outlier","Normal") -> Normal | H64: =IF(OR(D64<outliers!$B$21,D64>outliers!$B$20),"Outlier","Normal") -> Normal | I64: =IF(OR(E64<outliers!$C$28,E64>outliers!$B$27),"Outlier","Normal") -> Normal | J64: =YEAR(A64) -> 2017 | K64: =TEXT(A63,"mmmm") -> June | Q64: April | R64: 2746.8 | S64: 564
A65: 42910 | B65: 24.4 | C65: 21 | D65: 30.5 | E65: 0 | F65: =IF(OR(B65<outliers!$B$7,B65>outliers!$B$6),"Outlier","Normal") -> Normal | G65: =IF(OR(C65<outliers!$B$14,C65>outliers!$B$13),"Outlier","Normal") -> Normal | H65: =IF(OR(D65<outliers!$B$21,D65>outliers!$B$20),"Outlier","Normal") -> Normal | I65: =IF(OR(E65<outliers!$C$28,E65>outliers!$B$27),"Outlier","Normal") -> Normal | J65: =YEAR(A65) -> 2017 | K65: =TEXT(A64,"mmmm") -> June | Q65: May | R65: 3533.3 | S65: 1124.8
A66: 42911 | B66: 23.8 | C66: 20.6 | D66: 29.4 | E66: 0 | F66: =IF(OR(B66<outliers!$B$7,B66>outliers!$B$6),"Outlier","Normal") -> Normal | G66: =IF(OR(C66<outliers!$B$14,C66>outliers!$B$13),"Outlier","Normal") -> Normal | H66: =IF(OR(D66<outliers!$B$21,D66>outliers!$B$20),"Outlier","Normal") -> Normal | I66: =IF(OR(E66<outliers!$C$28,E66>outliers!$B$27),"Outlier","Normal") -> Normal | J66: =YEAR(A66) -> 2017 | K66: =TEXT(A65,"mmmm") -> June | Q66: June | R66: 3742.8 | S66: 626.9
A67: 42912 | B67: 24 | C67: 20.4 | D67: 29 | E67: 0 | F67: =IF(OR(B67<outliers!$B$7,B67>outliers!$B$6),"Outlier","Normal") -> Normal | G67: =IF(OR(C67<outliers!$B$14,C67>outliers!$B$13),"Outlier","Normal") -> Normal | H67: =IF(OR(D67<outliers!$B$21,D67>outliers!$B$20),"Outlier","Normal") -> Normal | I67: =IF(OR(E67<outliers!$C$28,E67>outliers!$B$27),"Outlier","Normal") -> Normal | J67: =YEAR(A67) -> 2017 | K67: =TEXT(A66,"mmmm") -> June | Q67: July | R67: 3833.6 | S67: 717.8
A68: 42913 | B68: 23.6 | C68: 20.4 | D68: 30.6 | E68: 0 | F68: =IF(OR(B68<outliers!$B$7,B68>outliers!$B$6),"Outlier","Normal") -> Normal | G68: =IF(OR(C68<outliers!$B$14,C68>outliers!$B$13),"Outlier","Normal") -> Normal | H68: =IF(OR(D68<outliers!$B$21,D68>outliers!$B$20),"Outlier","Normal") -> Normal | I68: =IF(OR(E68<outliers!$C$28,E68>outliers!$B$27),"Outlier","Normal") -> Normal | J68: =YEAR(A68) -> 2017 | K68: =TEXT(A67,"mmmm") -> June | Q68: August | R68: 3294.8 | S68: 890.2
A69: 42914 | B69: 24.3 | C69: 20.3 | D69: 29.8 | E69: 0 | F69: =IF(OR(B69<outliers!$B$7,B69>outliers!$B$6),"Outlier","Normal") -> Normal | G69: =IF(OR(C69<outliers!$B$14,C69>outliers!$B$13),"Outlier","Normal") -> Normal | H69: =IF(OR(D69<outliers!$B$21,D69>outliers!$B$20),"Outlier","Normal") -> Normal | I69: =IF(OR(E69<outliers!$C$28,E69>outliers!$B$27),"Outlier","Normal") -> Normal | J69: =YEAR(A69) -> 2017 | K69: =TEXT(A68,"mmmm") -> June | Q69: September | R69: 3132 | S69: 1210.8
A70: 42915 | B70: 24.3 | C70: 20.4 | D70: 29.1 | E70: 0 | F70: =IF(OR(B70<outliers!$B$7,B70>outliers!$B$6),"Outlier","Normal") -> Normal | G70: =IF(OR(C70<outliers!$B$14,C70>outliers!$B$13),"Outlier","Normal") -> Normal | H70: =IF(OR(D70<outliers!$B$21,D70>outliers!$B$20),"Outlier","Normal") -> Normal | I70: =IF(OR(E70<outliers!$C$28,E70>outliers!$B$27),"Outlier","Normal") -> Normal | J70: =YEAR(A70) -> 2017 | K70: =TEXT(A69,"mmmm") -> June | Q70: October | R70: 2863.6 | S70: 1257.6
A71: 42917 | B71: 24.6 | C71: 19.3 | D71: 29.2 | E71: 0 | F71: =IF(OR(B71<outliers!$B$7,B71>outliers!$B$6),"Outlier","Normal") -> Normal | G71: =IF(OR(C71<outliers!$B$14,C71>outliers!$B$13),"Outlier","Normal") -> Normal | H71: =IF(OR(D71<outliers!$B$21,D71>outliers!$B$20),"Outlier","Normal") -> Normal | I71: =IF(OR(E71<outliers!$C$28,E71>outliers!$B$27),"Outlier","Normal") -> Normal | J71: =YEAR(A71) -> 2017 | K71: =TEXT(A70,"mmmm") -> June | Q71: November | R71: 1944.8 | S71: 463.9
A72: 42918 | B72: 25.2 | C72: 20.5 | D72: 30.3 | E72: 0 | F72: =IF(OR(B72<outliers!$B$7,B72>outliers!$B$6),"Outlier","Normal") -> Normal | G72: =IF(OR(C72<outliers!$B$14,C72>outliers!$B$13),"Outlier","Normal") -> Normal | H72: =IF(OR(D72<outliers!$B$21,D72>outliers!$B$20),"Outlier","Normal") -> Normal | I72: =IF(OR(E72<outliers!$C$28,E72>outliers!$B$27),"Outlier","Normal") -> Normal | J72: =YEAR(A72) -> 2017 | K72: =TEXT(A71,"mmmm") -> July | Q72: December | R72: 1321.8 | S72: 74
A73: 42920 | B73: 23.7 | C73: 20.4 | D73: 28.7 | E73: 3.8 | F73: =IF(OR(B73<outliers!$B$7,B73>outliers!$B$6),"Outlier","Normal") -> Normal | G73: =IF(OR(C73<outliers!$B$14,C73>outliers!$B$13),"Outlier","Normal") -> Normal | H73: =IF(OR(D73<outliers!$B$21,D73>outliers!$B$20),"Outlier","Normal") -> Normal | I73: =IF(OR(E73<outliers!$C$28,E73>outliers!$B$27),"Outlier","Normal") -> Normal | J73: =YEAR(A73) -> 2017 | K73: =TEXT(A72,"mmmm") -> July | Q73: Grand Total | R73: 31587.4 | S73: 7078.7
A74: 42921 | B74: 23.2 | C74: 20 | D74: 29.6 | E74: 2.3 | F74: =IF(OR(B74<outliers!$B$7,B74>outliers!$B$6),"Outlier","Normal") -> Normal | G74: =IF(OR(C74<outliers!$B$14,C74>outliers!$B$13),"Outlier","Normal") -> Normal | H74: =IF(OR(D74<outliers!$B$21,D74>outliers!$B$20),"Outlier","Normal") -> Normal | I74: =IF(OR(E74<outliers!$C$28,E74>outliers!$B$27),"Outlier","Normal") -> Normal | J74: =YEAR(A74) -> 2017 | K74: =TEXT(A73,"mmmm") -> July
A75: 42922 | B75: 23.7 | C75: 20.2 | D75: 29.2 | E75: 10.2 | F75: =IF(OR(B75<outliers!$B$7,B75>outliers!$B$6),"Outlier","Normal") -> Normal | G75: =IF(OR(C75<outliers!$B$14,C75>outliers!$B$13),"Outlier","Normal") -> Normal | H75: =IF(OR(D75<outliers!$B$21,D75>outliers!$B$20),"Outlier","Normal") -> Normal | I75: =IF(OR(E75<outliers!$C$28,E75>outliers!$B$27),"Outlier","Normal") -> Normal | J75: =YEAR(A75) -> 2017 | K75: =TEXT(A74,"mmmm") -> July
A76: 42923 | B76: 23.2 | C76: 20.5 | D76: 29.3 | E76: 5.1 | F76: =IF(OR(B76<outliers!$B$7,B76>outliers!$B$6),"Outlier","Normal") -> Normal | G76: =IF(OR(C76<outliers!$B$14,C76>outliers!$B$13),"Outlier","Normal") -> Normal | H76: =IF(OR(D76<outliers!$B$21,D76>outliers!$B$20),"Outlier","Normal") -> Normal | I76: =IF(OR(E76<outliers!$C$28,E76>outliers!$B$27),"Outlier","Normal") -> Normal | J76: =YEAR(A76) -> 2017 | K76: =TEXT(A75,"mmmm") -> July
A77: 42924 | B77: 23.3 | C77: 20.4 | D77: 27.4 | E77: 0 | F77: =IF(OR(B77<outliers!$B$7,B77>outliers!$B$6),"Outlier","Normal") -> Normal | G77: =IF(OR(C77<outliers!$B$14,C77>outliers!$B$13),"Outlier","Normal") -> Normal | H77: =IF(OR(D77<outliers!$B$21,D77>outliers!$B$20),"Outlier","Normal") -> Normal | I77: =IF(OR(E77<outliers!$C$28,E77>outliers!$B$27),"Outlier","Normal") -> Normal | J77: =YEAR(A77) -> 2017 | K77: =TEXT(A76,"mmmm") -> July
A78: 42925 | B78: 24.5 | C78: 20.2 | D78: 30.3 | E78: 0 | F78: =IF(OR(B78<outliers!$B$7,B78>outliers!$B$6),"Outlier","Normal") -> Normal | G78: =IF(OR(C78<outliers!$B$14,C78>outliers!$B$13),"Outlier","Normal") -> Normal | H78: =IF(OR(D78<outliers!$B$21,D78>outliers!$B$20),"Outlier","Normal") -> Normal | I78: =IF(OR(E78<outliers!$C$28,E78>outliers!$B$27),"Outlier","Normal") -> Normal | J78: =YEAR(A78) -> 2017 | K78: =TEXT(A77,"mmmm") -> July
A79: 42928 | B79: 23.7 | C79: 21 | D79: 29.5 | E79: 0 | F79: =IF(OR(B79<outliers!$B$7,B79>outliers!$B$6),"Outlier","Normal") -> Normal | G79: =IF(OR(C79<outliers!$B$14,C79>outliers!$B$13),"Outlier","Normal") -> Normal | H79: =IF(OR(D79<outliers!$B$21,D79>outliers!$B$20),"Outlier","Normal") -> Normal | I79: =IF(OR(E79<outliers!$C$28,E79>outliers!$B$27),"Outlier","Normal") -> Normal | J79: =YEAR(A79) -> 2017 | K79: =TEXT(A78,"mmmm") -> July | Q79: Row Labels | R79: Average of tavg | S79: Sum of prcp
A80: 42929 | B80: 22.8 | C80: 20 | D80: 28.5 | E80: 1.5 | F80: =IF(OR(B80<outliers!$B$7,B80>outliers!$B$6),"Outlier","Normal") -> Normal | G80: =IF(OR(C80<outliers!$B$14,C80>outliers!$B$13),"Outlier","Normal") -> Normal | H80: =IF(OR(D80<outliers!$B$21,D80>outliers!$B$20),"Outlier","Normal") -> Normal | I80: =IF(OR(E80<outliers!$C$28,E80>outliers!$B$27),"Outlier","Normal") -> Normal | J80: =YEAR(A80) -> 2017 | K80: =TEXT(A79,"mmmm") -> July | Q80: 2017 | R80: 24.202162 | S80: 1693.4
A81: 42930 | B81: 22.9 | C81: 20 | D81: 25.9 | E81: 0 | F81: =IF(OR(B81<outliers!$B$7,B81>outliers!$B$6),"Outlier","Normal") -> Normal | G81: =IF(OR(C81<outliers!$B$14,C81>outliers!$B$13),"Outlier","Normal") -> Normal | H81: =IF(OR(D81<outliers!$B$21,D81>outliers!$B$20),"Outlier","Normal") -> Normal | I81: =IF(OR(E81<outliers!$C$28,E81>outliers!$B$27),"Outlier","Normal") -> Normal | J81: =YEAR(A81) -> 2017 | K81: =TEXT(A80,"mmmm") -> July | Q81: 2018 | R81: 23.969565 | S81: 911.1
A82: 42931 | B82: 22.2 | C82: 20.2 | D82: 27.2 | E82: 0 | F82: =IF(OR(B82<outliers!$B$7,B82>outliers!$B$6),"Outlier","Normal") -> Normal | G82: =IF(OR(C82<outliers!$B$14,C82>outliers!$B$13),"Outlier","Normal") -> Normal | H82: =IF(OR(D82<outliers!$B$21,D82>outliers!$B$20),"Outlier","Normal") -> Normal | I82: =IF(OR(E82<outliers!$C$28,E82>outliers!$B$27),"Outlier","Normal") -> Normal | J82: =YEAR(A82) -> 2017 | K82: =TEXT(A81,"mmmm") -> July | Q82: 2019 | R82: 23.965241 | S82: 897.5
A83: 42932 | B83: 23.2 | C83: 19.7 | D83: 28.4 | E83: 0 | F83: =IF(OR(B83<outliers!$B$7,B83>outliers!$B$6),"Outlier","Normal") -> Normal | G83: =IF(OR(C83<outliers!$B$14,C83>outliers!$B$13),"Outlier","Normal") -> Normal | H83: =IF(OR(D83<outliers!$B$21,D83>outliers!$B$20),"Outlier","Normal") -> Normal | I83: =IF(OR(E83<outliers!$C$28,E83>outliers!$B$27),"Outlier","Normal") -> Normal | J83: =YEAR(A83) -> 2017 | K83: =TEXT(A82,"mmmm") -> July | Q83: 2020 | R83: 23.687192 | S83: 1175.2
A84: 42933 | B84: 23.8 | C84: 20 | D84: 28.8 | E84: 0 | F84: =IF(OR(B84<outliers!$B$7,B84>outliers!$B$6),"Outlier","Normal") -> Normal | G84: =IF(OR(C84<outliers!$B$14,C84>outliers!$B$13),"Outlier","Normal") -> Normal | H84: =IF(OR(D84<outliers!$B$21,D84>outliers!$B$20),"Outlier","Normal") -> Normal | I84: =IF(OR(E84<outliers!$C$28,E84>outliers!$B$27),"Outlier","Normal") -> Normal | J84: =YEAR(A84) -> 2017 | K84: =TEXT(A83,"mmmm") -> July | Q84: 2021 | R84: 23.581944 | S84: 1593
A85: 42934 | B85: 22.8 | C85: 20.7 | D85: 28.3 | E85: 0 | F85: =IF(OR(B85<outliers!$B$7,B85>outliers!$B$6),"Outlier","Normal") -> Normal | G85: =IF(OR(C85<outliers!$B$14,C85>outliers!$B$13),"Outlier","Normal") -> Normal | H85: =IF(OR(D85<outliers!$B$21,D85>outliers!$B$20),"Outlier","Normal") -> Normal | I85: =IF(OR(E85<outliers!$C$28,E85>outliers!$B$27),"Outlier","Normal") -> Normal | J85: =YEAR(A85) -> 2017 | K85: =TEXT(A84,"mmmm") -> July | Q85: 2022 | R85: 23.997087 | S85: 808.5
...

Sheet building
A3: Year | B3: Row Labels | C3: Sum of tavg | D3: Sum of prcp
A4: 2017 | B4: 1 | C4: 4477.4 | D4: 1693.4
A5: 2018 | B5: 2 | C5: 4410.4 | D5: 911.1
A6: 2019 | B6: 3 | C6: 4481.5 | D6: 897.5
A7: 2020 | B7: 4 | C7: 4808.5 | D7: 1175.2
A8: 2021 | B8: 5 | C8: 8489.5 | D8: 1593
B9: Grand Total | C9: 26667.3 | D9: 6270.2
A11: R^2 value: | B11: 0.9075 | C11: 0.9266
A12: polynomial regression: | B12: y = 553.71x2 - 2480x + 6682.7 | C12: y = 192.25x2 - 1147.2x + 2580.8
A20: R^2 value: | B20: 0.5654 | C20: y = 842.23x + 2806.8
A21: polynomial regression: | B21: 0.0007 | C21: y = 6.33x + 1235.1

Sheet testing
A2: time | B2: tavg | C2: tmin | D2: tmax | E2: prcp | F2: is outlier B | G2: is outlier C | H2: is outlier D | I2: is outlier E | J2: Year | K2: MONTH
A3: 44562 | B3: 21.4 | C3: 18.5 | D3: 24.6 | E3: 3.3 | F3: Normal | G3: Normal | H3: Normal | I3: Normal | J3: 2022 | K3: =MONTH(A3) -> 1
A4: 44563 | B4: 22 | C4: 17.5 | D4: 26.4 | E4: 0 | F4: Normal | G4: Normal | H4: Normal | I4: Normal | J4: 2022 | K4: =MONTH(A4) -> 1
A5: 44569 | B5: 21.6 | C5: 17.2 | D5: 27.2 | E5: 0 | F5: Normal | G5: Normal | H5: Normal | I5: Normal | J5: 2022 | K5: =MONTH(A5) -> 1
A6: 44570 | B6: 21.7 | C6: 17.3 | D6: 27.2 | E6: 0 | F6: Normal | G6: Normal | H6: Normal | I6: Normal | J6: 2022 | K6: =MONTH(A6) -> 1
A7: 44573 | B7: 22.4 | C7: 18.3 | D7: 28.6 | E7: 0.4 | F7: Normal | G7: Normal | H7: Normal | I7: Normal | J7: 2022 | K7: =MONTH(A7) -> 1
A8: 44574 | B8: 22.1 | C8: 17.5 | D8: 27.4 | E8: 0.5 | F8: Normal | G8: Normal | H8: Normal | I8: Normal | J8: 2022 | K8: =MONTH(A8) -> 1
A9: 44575 | B9: 21.8 | C9: 17.8 | D9: 27.4 | E9: 0.2 | F9: Normal | G9: Normal | H9: Normal | I9: Normal | J9: 2022 | K9: =MONTH(A9) -> 1
A10: 44577 | B10: 21.9 | C10: 17.4 | D10: 27.6 | E10: 0.2 | F10: Normal | G10: Normal | H10: Normal | I10: Normal | J10: 2022 | K10: =MONTH(A10) -> 1
A11: 44587 | B11: 22.2 | C11: 17.3 | D11: 28 | E11: 0.1 | F11: Normal | G11: Normal | H11: Normal | I11: Normal | J11: 2022 | K11: =MONTH(A11) -> 1
A12: 44588 | B12: 21.5 | C12: 17.9 | D12: 25.4 | E12: 1.8 | F12: Normal | G12: Normal | H12: Normal | I12: Normal | J12: 2022 | K12: =MONTH(A12) -> 1
A13: 44589 | B13: 21.1 | C13: 17 | D13: 26.3 | E13: 0 | F13: Normal | G13: Normal | H13: Normal | I13: Normal | J13: 2022 | K13: =MONTH(A13) -> 1
A14: 44591 | B14: 23 | C14: 18.1 | D14: 29.4 | E14: 0 | F14: Normal | G14: Normal | H14: Normal | I14: Normal | J14: 2022 | K14: =MONTH(A14) -> 1
... A140: 44767 | B140: 24.1 | C140: 20.2 | D140: 28.5 | E140: 0.5 | F140: Normal | G140: Normal | H140: Normal | I140: Normal | J140: 2022 | K140: =MONTH(A140) -> 7
D142: PREDICTED VALUES | F142: PREDICTED VALUES
A143: Row Labels | B143: Sum of tavg | C143: Sum of prcp | D143: Sum of tavg | E143: Sum of prcp | F143: Sum of tavg | G143: Sum of prcp
A144: 6 | B144: 3367.7 | C144: 160.2 | D144: =( 553.71*(A144*A144) - 2480*A144 + 6682.7) -> 11736.26 | E144: =192.25*(A144^2) - 1147.2*A144 + 2580.8 -> 2618.6 | F144: =842.23*A144 + 2806.8 -> 7860.18 | G144: =6.33*A144+ 1235.1 -> 1273.08
A145: Grand Total | B145: 3367.7 | C145: 160.2

Sheet training
A1: BUILDING REGRESSION MODEL
A3: time | B3: tavg | C3: tmin | D3: tmax | E3: prcp | F3: is outlier B | G3: is outlier C | H3: is outlier D | I3: is outlier E | J3: month | K3: month2
A4: 42757 | B4: 23.3 | C4: 16.8 | D4: 29.1 | E4: 0 | F4: =IF(OR(B4<outliers!$B$7,B4>outliers!$B$6),"Outlier","Normal") -> Normal | G4: =IF(OR(C4<outliers!$B$14,C4>outliers!$B$13),"Outlier","Normal") -> Outlier | H4: =IF(OR(D4<outliers!$B$21,D4>outliers!$B$20),"Outlier","Normal") -> Normal | I4: =IF(OR(E4<outliers!$C$28,E4>outliers!$B$27),"Outlier","Normal") -> Normal | J4: =YEAR(A4) -> 2017 | K4: =MONTH(A4) -> 1
A5: 42761 | B5: 21.9 | C5: 18.3 | D5: 29.2 | E5: 0 | F5: =IF(OR(B5<outliers!$B$7,B5>outliers!$B$6),"Outlier","Normal") -> Normal | G5: =IF(OR(C5<outliers!$B$14,C5>outliers!$B$13),"Outlier","Normal") -> Normal | H5: =IF(OR(D5<outliers!$B$21,D5>outliers!$B$20),"Outlier","Normal") -> Normal | I5: =IF(OR(E5<outliers!$C$28,E5>outliers!$B$27),"Outlier","Normal") -> Normal | J5: =YEAR(A5) -> 2017 | K5: =MONTH(A5) -> 1
A6: 42762 | B6: 22.1 | C6: 19.7 | D6: 26 | E6: 0.3 | F6: =IF(OR(B6<outliers!$B$7,B6>outliers!$B$6),"Outlier","Normal") -> Normal | G6: =IF(OR(C6<outliers!$B$14,C6>outliers!$B$13),"Outlier","Normal") -> Normal | H6: =IF(OR(D6<outliers!$B$21,D6>outliers!$B$20),"Outlier","Normal") -> Normal | I6: =IF(OR(E6<outliers!$C$28,E6>outliers!$B$27),"Outlier","Normal") -> Normal | J6: =YEAR(A6) -> 2017 | K6: =MONTH(A6) -> 1
A7: 42763 | B7: 22.7 | C7: 20 | D7: 26.7 | E7: 0 | F7: =IF(OR(B7<outliers!$B$7,B7>outliers!$B$6),"Outlier","Normal") -> Normal | G7: =IF(OR(C7<outliers!$B$14,C7>outliers!$B$13),"Outlier","Normal") -> Normal | H7: =IF(OR(D7<outliers!$B$21,D7>outliers!$B$20),"Outlier","Normal") -> Normal | I7: =IF(OR(E7<outliers!$C$28,E7>outliers!$B$27),"Outlier","Normal") -> Normal | J7: =YEAR(A7) -> 2017 | K7: =MONTH(A7) -> 1
A8: 42764 | B8: 23.7 | C8: 19.2 | D8: 29 | E8: 0 | F8: =IF(OR(B8<outliers!$B$7,B8>outliers!$B$6),"Outlier","Normal") -> Normal | G8: =IF(OR(C8<outliers!$B$14,C8>outliers!$B$13),"Outlier","Normal") -> Normal | H8: =IF(OR(D8<outliers!$B$21,D8>outliers!$B$20),"Outlier","Normal") -> Normal | I8: =IF(OR(E8<outliers!$C$28,E8>outliers!$B$27),"Outlier","Normal") -> Normal | J8: =YEAR(A8) -> 2017 | K8: =MONTH(A8) -> 1
A9: 42801 | B9: 26.2 | C9: 21.5 | D9: 33.1 | E9: 8.4 | F9: =IF(OR(B9<outliers!$B$7,B9>outliers!$B$6),"Outlier","Normal") -> Normal | G9: =IF(OR(C9<outliers!$B$14,C9>outliers!$B$13),"Outlier","Normal") -> Normal | H9: =IF(OR(D9<outliers!$B$21,D9>outliers!$B$20),"Outlier","Normal") -> Normal | I9: =IF(OR(E9<outliers!$C$28,E9>outliers!$B$27),"Outlier","Normal") -> Normal | J9: =YEAR(A9) -> 2017 | K9: =MONTH(A9) -> 3
A10: 42802 | B10: 25.6 | C10: 21.1 | D10: 33.8 | E10: 36.8 | F10: =IF(OR(B10<outliers!$B$7,B10>outliers!$B$6),"Outlier","Normal") -> Normal | G10: =IF(OR(C10<outliers!$B$14,C10>outliers!$B$13),"Outlier","Normal") -> Normal | H10: =IF(OR(D10<outliers!$B$21,D10>outliers!$B$20),"Outlier","Normal") -> Normal | I10: =IF(OR(E10<outliers!$C$28,E10>outliers!$B$27),"Outlier","Normal") -> Outlier | J10: =YEAR(A10) -> 2017 | K10: =MONTH(A10) -> 3
A11: 42803 | B11: 26.7 | C11: 21.2 | D11: 32.1 | E11: 0 | F11: =IF(OR(B11<outliers!$B$7,B11>outliers!$B$6),"Outlier","Normal") -> Normal | G11: =IF(OR(C11<outliers!$B$14,C11>outliers!$B$13),"Outlier","Normal") -> Normal | H11: =IF(OR(D11<outliers!$B$21,D11>outliers!$B$20),"Outlier","Normal") -> Normal | I11: =IF(OR(E11<outliers!$C$28,E11>outliers!$B$27),"Outlier","Normal") -> Normal | J11: =YEAR(A11) -> 2017 | K11: =MONTH(A11) -> 3
A12: 42805 | B12: 27.2 | C12: 21 | D12: 33.5 | E12: 0 | F12: =IF(OR(B12<outliers!$B$7,B12>outliers!$B$6),"Outlier","Normal") -> Normal | G12: =IF(OR(C12<outliers!$B$14,C12>outliers!$B$13),"Outlier","Normal") -> Normal | H12: =IF(OR(D12<outliers!$B$21,D12>outliers!$B$20),"Outlier","Normal") -> Normal | I12: =IF(OR(E12<outliers!$C$28,E12>outliers!$B$27),"Outlier","Normal") -> Normal | J12: =YEAR(A12) -> 2017 | K12: =MONTH(A12) -> 3
A13: 42808 | B13: 25.1 | C13: 22 | D13: 34 | E13: 0 | F13: =IF(OR(B13<outliers!$B$7,B13>outliers!$B$6),"Outlier","Normal") -> Normal | G13: =IF(OR(C13<outliers!$B$14,C13>outliers!$B$13),"Outlier","Normal") -> Normal | H13: =IF(OR(D13<outliers!$B$21,D13>outliers!$B$20),"Outlier","Normal") -> Normal | I13: =IF(OR(E13<outliers!$C$28,E13>outliers!$B$27),"Outlier","Normal") -> Normal | J13: =YEAR(A13) -> 2017 | K13: =MONTH(A13) -> 3
A14: 42809 | B14: 25.3 | C14: 20.8 | D14: 30.4 | E14: 0 | F14: =IF(OR(B14<outliers!$B$7,B14>outliers!$B$6),"Outlier","Normal") -> Normal | G14: =IF(OR(C14<outliers!$B$14,C14>outliers!$B$13),"Outlier","Normal") -> Normal | H14: =IF(OR(D14<outliers!$B$21,D14>outliers!$B$20),"Outlier","Normal") -> Normal | I14: =IF(OR(E14<outliers!$C$28,E14>outliers!$B$27),"Outlier","Normal") -> Normal | J14: =YEAR(A14) -> 2017 | K14: =MONTH(A14) -> 3
A15: 42830 | B15: 27.3 | C15: 21.2 | D15: 36.1 | E15: 0 | F15: =IF(OR(B15<outliers!$B$7,B15>outliers!$B$6),"Outlier","Normal") -> Normal | G15: =IF(OR(C15<outliers!$B$14,C15>outliers!$B$13),"Outlier","Normal") -> Normal | H15: =IF(OR(D15<outliers!$B$21,D15>outliers!$B$20),"Outlier","Normal") -> Normal | I15: =IF(OR(E15<outliers!$C$28,E15>outliers!$B$27),"Outlier","Normal") -> Normal | J15: =YEAR(A15) -> 2017 | K15: =MONTH(A15) -> 4
... A1122: 44561 | B1122: 20.3 | C1122: 17.6 | D1122: 26.5 | E1122: 0 | F1122: =IF(OR(B1122<outliers!$B$7,B1122>outliers!$B$6),"Outlier","Normal") -> Normal | G1122: =IF(OR(C1122<outliers!$B$14,C1122>outliers!$B$13),"Outlier","Normal") -> Normal | H1122: =IF(OR(D1122<outliers!$B$21,D1122>outliers!$B$20),"Outlier","Normal") -> Normal | I1122: =IF(OR(E1122<outliers!$C$28,E1122>outliers!$B$27),"Outlier","Normal") -> Normal | J1122: =YEAR(A1122) -> 2021 | K1122: =MONTH(A1122) -> 12

Sheet monthly_testing
A1: TRAINING
A3: Row Labels | B3: Sum of tavg | C3: Sum of prcp
A4: 1 | B4: 643.7 | C4: 18.8
A5: 2 | B5: 430.6 | C5: 9.9
A6: 3 | B6: 1205.9 | C6: 19.8
A7: 4 | B7: 1450.5 | C7: 47.9
A8: 5 | B8: 1925.7 | C8: 99.6
A9: 6 | B9: 2767.8 | C9: 130.6
A10: 7 | B10: 2856.4 | C10: 183
A11: 8 | B11: 2718.8 | C11: 209.5
A12: 9 | B12: 2395.8 | C12: 146.9
A13: 10 | B13: 2111.1 | C13: 199.4
A14: 11 | B14: 1664.2 | C14: 98
A15: 12 | B15: 992.1 | C15: 56.3
A16: Grand Total | B16: 21162.6 | C16: 1219.7
A19: TESTING
A21: Row Labels | B21: Sum of tavg | C21: Sum of prcp
A22: 1 | B22: 286.1 | C22: 6.5
A23: 2 | B23: 115.9 | C23: 0
A24: 3 | B24: 647.2 | C24: 16.5
A25: 4 | B25: 616.1 | C25: 4.5
A26: 5 | B26: 631.1 | C26: 57.4
A27: 6 | B27: 547.5 | C27: 42.6
A28: 7 | B28: 523.8 | C28: 32.7
A29: Grand Total | B29: 3367.7 | C29: 160.2

Sheet monthly_training
A2: time | B2: tavg | C2: tmin | D2: tmax | E2: prcp | F2: is outlier B | G2: is outlier C | H2: is outlier D | I2: is outlier E | J2: year | K2: month
A3: 42761 | B3: 21.9 | C3: 18.3 | D3: 29.2 | E3: 0 | F3: Normal | G3: Normal | H3: Normal | I3: Normal | J3: 2017 | K3: 1
A4: 42762 | B4: 22.1 | C4: 19.7 | D4: 26 | E4: 0.3 | F4: Normal | G4: Normal | H4: Normal | I4: Normal | J4: 2017 | K4: 1
A5: 42763 | B5: 22.7 | C5: 20 | D5: 26.7 | E5: 0 | F5: Normal | G5: Normal | H5: Normal | I5: Normal | J5: 2017 | K5: 1
A6: 42764 | B6: 23.7 | C6: 19.2 | D6: 29 | E6: 0 | F6: Normal | G6: Normal | H6: Normal | I6: Normal | J6: 2017 | K6: 1
A7: 42801 | B7: 26.2 | C7: 21.5 | D7: 33.1 | E7: 8.4 | F7: Normal | G7: Normal | H7: Normal | I7: Normal | J7: 2017 | K7: 3
A8: 42803 | B8: 26.7 | C8: 21.2 | D8: 32.1 | E8: 0 | F8: Normal | G8: Normal | H8: Normal | I8: Normal | J8: 2017 | K8: 3
A9: 42805 | B9: 27.2 | C9: 21 | D9: 33.5 | E9: 0 | F9: Normal | G9: Normal | H9: Normal | I9: Normal | J9: 2017 | K9: 3
A10: 42808 | B10: 25.1 | C10: 22 | D10: 34 | E10: 0 | F10: Normal | G10: Normal | H10: Normal | I10: Normal | J10: 2017 | K10: 3
A11: 42809 | B11: 25.3 | C11: 20.8 | D11: 30.4 | E11: 0 | F11: Normal | G11: Normal | H11: Normal | I11: Normal | J11: 2017 | K11: 3
A12: 42830 | B12: 27.3 | C12: 21.2 | D12: 36.1 | E12: 0 | F12: Normal | G12: Normal | H12: Normal | I12: Normal | J12: 2017 | K12: 4
A13: 42831 | B13: 27.8 | C13: 22.4 | D13: 35.5 | E13: 3.6 | F13: Normal | G13: Normal | H13: Normal | I13: Normal | J13: 2017 | K13: 4
A14: 42842 | B14: 25.7 | C14: 22.2 | D14: 36.2 | E14: 0.5 | F14: Normal | G14: Normal | H14: Normal | I14: Normal | J14: 2017 | K14: 4
... A886: 44561 | B886: 20.3 | C886: 17.6 | D886: 26.5 | E886: 0 | F886: Normal | G886: Normal | H886: Normal | I886: Normal | J886: 2021 | K886: 12

Sheet outliers
A1: To Find thew outliers
A2: for tavg:
A3: Quartile 1 | B3: =QUARTILE(DATA!B2:B1326,1) -> 22.6
A4: Quartile 3 | B4: =QUARTILE(DATA!B2:B1326,3) -> 24.9
A5: IQR | B5: =B4-B3 -> 2.3
A6: Upper limit | B6: =B4+B5*1.5 -> 28.35
A7: Lower limit | B7: =B3-B5*1.5 -> 19.15
A9: for tmin:
A10: Quartile 1 | B10: =QUARTILE(DATA!C9:C1333,1) -> 19.3
A11: Quartile 3 | B11: =QUARTILE(DATA!C9:C1333,3) -> 20.9
A12: IQR | B12: =B11-B10 -> 1.6
A13: Upper limit | B13: =B11+B12*1.5 -> 23.3
A14: Lower limit | B14: =B10-B12*1.5 -> 16.9
A16: for tmax:
A17: Quartile 1 | B17: =QUARTILE(DATA!D16:D1340,1) -> 27.6
A18: Quartile 3 | B18: =QUARTILE(DATA!D16:D1340,3) -> 31.1
A19: IQR | B19: =B18-B17 -> 3.5
A20: Upper limit | B20: =B18+B19*1.5 -> 36.35
A21: Lower limit | B21: =B17-B19*1.5 -> 22.35
A23: for prcp:
A24: Quartile 1 | B24: =QUARTILE(DATA!E21:E1347,1) -> 0
A25: Quartile 3 | B25: =QUARTILE(DATA!E21:E1347,3) -> 4.1
A26: IQR | B26: =B25-B24 -> 4.1
A27: Upper limit | B27: =B25+B26*1.5 -> 10.25
A28: Lower limit | B28: =B24-B26*1.5 -> -6.15 | C28: 0
